<?xml version="1.0" encoding="UTF-8"?>
<!-- Generated by org.testng.reporters.JUnitReportReporter -->
<testsuite skipped="0" hostname="DESKTOP-KKIOJ2D" name="com.tictoc.testcases.VerifySavingsDDTonGrid" tests="9" failures="3" timestamp="03 Mar 2021 04:51:55 GMT" time="318.918" errors="0">
  <testcase name="VerifyRefiSavings" time="63.068" classname="com.tictoc.testcases.VerifySavingsDDTonGrid">
    <failure type="java.lang.AssertionError" message="Set test result to FAIL due to failed steps">
      <![CDATA[java.lang.AssertionError: Set test result to FAIL due to failed steps
at org.testng.Assert.fail(Assert.java:96)
at utilities.auto.TestNGListener.onTestSuccess(TestNGListener.java:55)
at org.testng.internal.TestListenerHelper.runTestListeners(TestListenerHelper.java:70)
at org.testng.internal.Invoker.runTestListeners(Invoker.java:1389)
at org.testng.internal.Invoker.invokeMethod(Invoker.java:636)
at org.testng.internal.Invoker.invokeTestMethod(Invoker.java:719)
at org.testng.internal.Invoker.invokeTestMethods(Invoker.java:989)
at org.testng.internal.TestMethodWorker.invokeTestMethods(TestMethodWorker.java:125)
at org.testng.internal.TestMethodWorker.run(TestMethodWorker.java:109)
at org.testng.TestRunner.privateRun(TestRunner.java:648)
at org.testng.TestRunner.run(TestRunner.java:505)
at org.testng.SuiteRunner.runTest(SuiteRunner.java:455)
at org.testng.SuiteRunner.access$000(SuiteRunner.java:40)
at org.testng.SuiteRunner$SuiteWorker.run(SuiteRunner.java:489)
at org.testng.internal.thread.ThreadUtil$1.call(ThreadUtil.java:52)
at java.util.concurrent.FutureTask.run(FutureTask.java:266)
at java.util.concurrent.ThreadPoolExecutor.runWorker(ThreadPoolExecutor.java:1149)
at java.util.concurrent.ThreadPoolExecutor$Worker.run(ThreadPoolExecutor.java:624)
at java.lang.Thread.run(Thread.java:748)
]]>
    </failure>
  </testcase> <!-- VerifyRefiSavings -->
  <testcase name="VerifyRefiSavings" time="19.093" classname="com.tictoc.testcases.VerifySavingsDDTonGrid"/>
  <testcase name="VerifyRefiSavings" time="66.607" classname="com.tictoc.testcases.VerifySavingsDDTonGrid">
    <failure type="java.lang.AssertionError" message="Set test result to FAIL due to failed steps">
      <![CDATA[java.lang.AssertionError: Set test result to FAIL due to failed steps
at org.testng.Assert.fail(Assert.java:96)
at utilities.auto.TestNGListener.onTestSuccess(TestNGListener.java:55)
at org.testng.internal.TestListenerHelper.runTestListeners(TestListenerHelper.java:70)
at org.testng.internal.Invoker.runTestListeners(Invoker.java:1389)
at org.testng.internal.Invoker.invokeMethod(Invoker.java:636)
at org.testng.internal.Invoker.invokeTestMethod(Invoker.java:719)
at org.testng.internal.Invoker.invokeTestMethods(Invoker.java:989)
at org.testng.internal.TestMethodWorker.invokeTestMethods(TestMethodWorker.java:125)
at org.testng.internal.TestMethodWorker.run(TestMethodWorker.java:109)
at org.testng.TestRunner.privateRun(TestRunner.java:648)
at org.testng.TestRunner.run(TestRunner.java:505)
at org.testng.SuiteRunner.runTest(SuiteRunner.java:455)
at org.testng.SuiteRunner.access$000(SuiteRunner.java:40)
at org.testng.SuiteRunner$SuiteWorker.run(SuiteRunner.java:489)
at org.testng.internal.thread.ThreadUtil$1.call(ThreadUtil.java:52)
at java.util.concurrent.FutureTask.run(FutureTask.java:266)
at java.util.concurrent.ThreadPoolExecutor.runWorker(ThreadPoolExecutor.java:1149)
at java.util.concurrent.ThreadPoolExecutor$Worker.run(ThreadPoolExecutor.java:624)
at java.lang.Thread.run(Thread.java:748)
]]>
    </failure>
  </testcase> <!-- VerifyRefiSavings -->
  <testcase name="VerifyRefiSavings" time="20.258" classname="com.tictoc.testcases.VerifySavingsDDTonGrid"/>
  <testcase name="VerifyRefiSavings" time="22.472" classname="com.tictoc.testcases.VerifySavingsDDTonGrid"/>
  <testcase name="VerifyRefiSavings" time="19.577" classname="com.tictoc.testcases.VerifySavingsDDTonGrid"/>
  <testcase name="VerifyRefiSavings" time="67.837" classname="com.tictoc.testcases.VerifySavingsDDTonGrid">
    <failure type="java.lang.AssertionError" message="Set test result to FAIL due to failed steps">
      <![CDATA[java.lang.AssertionError: Set test result to FAIL due to failed steps
at org.testng.Assert.fail(Assert.java:96)
at utilities.auto.TestNGListener.onTestSuccess(TestNGListener.java:55)
at org.testng.internal.TestListenerHelper.runTestListeners(TestListenerHelper.java:70)
at org.testng.internal.Invoker.runTestListeners(Invoker.java:1389)
at org.testng.internal.Invoker.invokeMethod(Invoker.java:636)
at org.testng.internal.Invoker.invokeTestMethod(Invoker.java:719)
at org.testng.internal.Invoker.invokeTestMethods(Invoker.java:989)
at org.testng.internal.TestMethodWorker.invokeTestMethods(TestMethodWorker.java:125)
at org.testng.internal.TestMethodWorker.run(TestMethodWorker.java:109)
at org.testng.TestRunner.privateRun(TestRunner.java:648)
at org.testng.TestRunner.run(TestRunner.java:505)
at org.testng.SuiteRunner.runTest(SuiteRunner.java:455)
at org.testng.SuiteRunner.access$000(SuiteRunner.java:40)
at org.testng.SuiteRunner$SuiteWorker.run(SuiteRunner.java:489)
at org.testng.internal.thread.ThreadUtil$1.call(ThreadUtil.java:52)
at java.util.concurrent.FutureTask.run(FutureTask.java:266)
at java.util.concurrent.ThreadPoolExecutor.runWorker(ThreadPoolExecutor.java:1149)
at java.util.concurrent.ThreadPoolExecutor$Worker.run(ThreadPoolExecutor.java:624)
at java.lang.Thread.run(Thread.java:748)
]]>
    </failure>
  </testcase> <!-- VerifyRefiSavings -->
  <testcase name="VerifyRefiSavings" time="20.994" classname="com.tictoc.testcases.VerifySavingsDDTonGrid"/>
  <testcase name="VerifyRefiSavings" time="19.012" classname="com.tictoc.testcases.VerifySavingsDDTonGrid"/>
</testsuite> <!-- com.tictoc.testcases.VerifySavingsDDTonGrid -->
